
    <mujoco model="trunk">
        <compiler angle="radian"/>
        <extension>
            <plugin plugin="mujoco.elasticity.cable">
            <instance name="compositeactuated">
                <config key="twist" value="1e8"/>
                <config key="bend" value="1e8"/>
                <config key="vmax" value="0"/>
            </instance>
            </plugin>
        </extension>

        <asset>
            <texture type="skybox" builtin="gradient" rgb1=".6 .8 1" rgb2=".6 .8 1" width="1" height="1"/>
        </asset>

        <worldbody>
            <light pos="0 -1 -1" dir="0 -1 -1" diffuse="1 1 1"/>
            <body name="actuatedB_first" pos="0 0 0.7" quat="0 -0.707107 0 0.707107">
                <geom name="actuatedG0" size="0.005 0.005" pos="0.005 0 0" quat="0.707107 0 -0.707107 0" type="capsule" rgba="0.8 0.2 0.1 1"/>
                
        <body name="link_1" pos="0.1 0 0">
            <joint name="joint_1" pos="0 0 0" type="ball" group="3" actuatorfrclimited="false" armature="0.01" damping="0.25"/>
            <geom name="geom_1" size="0.05 0.05" density="0.1" pos="0.05 0 0" quat="0.707107 0 -0.707107 0" type="capsule" rgba="0 0 0 1"/>
            <site name="site_y_front_1" pos="0 0.05 0"/> 
            <site name="site_y_back_1" pos="0 -0.05 0"/>
            <site name="site_z_front_1" pos="0 0 0.05"/> 
            <site name="site_z_back_1" pos="0 0 -0.05"/>
            
        <body name="link_2" pos="0.1 0 0">
            <joint name="joint_2" pos="0 0 0" type="ball" group="3" actuatorfrclimited="false" armature="0.01" damping="0.25"/>
            <geom name="geom_2" size="0.05 0.05" density="0.1" pos="0.05 0 0" quat="0.707107 0 -0.707107 0" type="capsule" rgba="0 0 0 1"/>
            <site name="site_y_front_2" pos="0 0.05 0"/> 
            <site name="site_y_back_2" pos="0 -0.05 0"/>
            <site name="site_z_front_2" pos="0 0 0.05"/> 
            <site name="site_z_back_2" pos="0 0 -0.05"/>
            
        <body name="link_3" pos="0.1 0 0">
            <joint name="joint_3" pos="0 0 0" type="ball" group="3" actuatorfrclimited="false" armature="0.01" damping="0.25"/>
            <geom name="geom_3" size="0.05 0.05" density="0.1" pos="0.05 0 0" quat="0.707107 0 -0.707107 0" type="capsule" rgba="0 0 0 1"/>
            <site name="site_y_front_3" pos="0 0.05 0"/> 
            <site name="site_y_back_3" pos="0 -0.05 0"/>
            <site name="site_z_front_3" pos="0 0 0.05"/> 
            <site name="site_z_back_3" pos="0 0 -0.05"/>
            
        <body name="link_4" pos="0.1 0 0">
            <joint name="joint_4" pos="0 0 0" type="ball" group="3" actuatorfrclimited="false" armature="0.01" damping="0.25"/>
            <geom name="geom_4" size="0.05 0.05" density="0.1" pos="0.05 0 0" quat="0.707107 0 -0.707107 0" type="capsule" rgba="0 0 0 1"/>
            <site name="site_y_front_4" pos="0 0.05 0"/> 
            <site name="site_y_back_4" pos="0 -0.05 0"/>
            <site name="site_z_front_4" pos="0 0 0.05"/> 
            <site name="site_z_back_4" pos="0 0 -0.05"/>
            
        <body name="link_5" pos="0.1 0 0">
            <joint name="joint_5" pos="0 0 0" type="ball" group="3" actuatorfrclimited="false" armature="0.01" damping="0.25"/>
            <geom name="geom_5" size="0.05 0.05" density="0.1" pos="0.05 0 0" quat="0.707107 0 -0.707107 0" type="capsule" rgba="0 0 0 1"/>
            <site name="site_y_front_5" pos="0 0.05 0"/> 
            <site name="site_y_back_5" pos="0 -0.05 0"/>
            <site name="site_z_front_5" pos="0 0 0.05"/> 
            <site name="site_z_back_5" pos="0 0 -0.05"/>
            
        <body name="link_6" pos="0.1 0 0">
            <joint name="joint_6" pos="0 0 0" type="ball" group="3" actuatorfrclimited="false" armature="0.01" damping="0.25"/>
            <geom name="geom_6" size="0.05 0.05" density="0.1" pos="0.05 0 0" quat="0.707107 0 -0.707107 0" type="capsule" rgba="0 0 0 1"/>
            <site name="site_y_front_6" pos="0 0.05 0"/> 
            <site name="site_y_back_6" pos="0 -0.05 0"/>
            <site name="site_z_front_6" pos="0 0 0.05"/> 
            <site name="site_z_back_6" pos="0 0 -0.05"/>
            
        <body name="link_7" pos="0.1 0 0">
            <joint name="joint_7" pos="0 0 0" type="ball" group="3" actuatorfrclimited="false" armature="0.01" damping="0.25"/>
            <geom name="geom_7" size="0.05 0.05" density="0.1" pos="0.05 0 0" quat="0.707107 0 -0.707107 0" type="capsule" rgba="0 0 0 1"/>
            <site name="site_y_front_7" pos="0 0.05 0"/> 
            <site name="site_y_back_7" pos="0 -0.05 0"/>
            <site name="site_z_front_7" pos="0 0 0.05"/> 
            <site name="site_z_back_7" pos="0 0 -0.05"/>
            
        <body name="link_8" pos="0.1 0 0">
            <joint name="joint_8" pos="0 0 0" type="ball" group="3" actuatorfrclimited="false" armature="0.01" damping="0.25"/>
            <geom name="geom_8" size="0.05 0.05" density="0.1" pos="0.05 0 0" quat="0.707107 0 -0.707107 0" type="capsule" rgba="0 0 0 1"/>
            <site name="site_y_front_8" pos="0 0.05 0"/> 
            <site name="site_y_back_8" pos="0 -0.05 0"/>
            <site name="site_z_front_8" pos="0 0 0.05"/> 
            <site name="site_z_back_8" pos="0 0 -0.05"/>
            
        <body name="link_9" pos="0.1 0 0">
            <joint name="joint_9" pos="0 0 0" type="ball" group="3" actuatorfrclimited="false" armature="0.01" damping="0.25"/>
            <geom name="geom_9" size="0.05 0.05" density="0.1" pos="0.05 0 0" quat="0.707107 0 -0.707107 0" type="capsule" rgba="0 0 0 1"/>
            <site name="site_y_front_9" pos="0 0.05 0"/> 
            <site name="site_y_back_9" pos="0 -0.05 0"/>
            <site name="site_z_front_9" pos="0 0 0.05"/> 
            <site name="site_z_back_9" pos="0 0 -0.05"/>
            
        <body name="link_10" pos="0.1 0 0">
            <joint name="joint_10" pos="0 0 0" type="ball" group="3" actuatorfrclimited="false" armature="0.01" damping="0.25"/>
            <geom name="geom_10" size="0.05 0.05" density="0.1" pos="0.05 0 0" quat="0.707107 0 -0.707107 0" type="capsule" rgba="0 0 0 1"/>
            <site name="site_y_front_10" pos="0 0.05 0"/> 
            <site name="site_y_back_10" pos="0 -0.05 0"/>
            <site name="site_z_front_10" pos="0 0 0.05"/> 
            <site name="site_z_back_10" pos="0 0 -0.05"/>
            
        <body name="link_0" pos="0.1 0 0">
            
            <geom name="geom_0" size="0.05 0.05" density="0.1" pos="0.05 0 0" quat="0.707107 0 -0.707107 0" type="capsule" rgba="0 0 0 1"/>
            <site name="site_y_front_0" pos="0 0.05 0"/> 
            <site name="site_y_back_0" pos="0 -0.05 0"/>
            <site name="site_z_front_0" pos="0 0 0.05"/> 
            <site name="site_z_back_0" pos="0 0 -0.05"/>
            
        </body>
    
        </body>
    
        </body>
    
        </body>
    
        </body>
    
        </body>
    
        </body>
    
        </body>
    
        </body>
    
        </body>
    
        </body>
    
            </body>
        </worldbody>

        
        <tendon>
            <spatial name="tendon_y_front" stiffness="0.01" damping="1.0" width="0.002">
                <site site="site_y_front_0"/>
<site site="site_y_front_1"/>
<site site="site_y_front_2"/>
<site site="site_y_front_3"/>
<site site="site_y_front_4"/>
<site site="site_y_front_5"/>
<site site="site_y_front_6"/>
<site site="site_y_front_7"/>
<site site="site_y_front_8"/>
<site site="site_y_front_9"/>
<site site="site_y_front_10"/>
            </spatial>
        </tendon>
    
        <tendon>
            <spatial name="tendon_y_back" stiffness="0.01" damping="1.0" width="0.002">
                <site site="site_y_back_0"/>
<site site="site_y_back_1"/>
<site site="site_y_back_2"/>
<site site="site_y_back_3"/>
<site site="site_y_back_4"/>
<site site="site_y_back_5"/>
<site site="site_y_back_6"/>
<site site="site_y_back_7"/>
<site site="site_y_back_8"/>
<site site="site_y_back_9"/>
<site site="site_y_back_10"/>
            </spatial>
        </tendon>
    
        <tendon>
            <spatial name="tendon_z_front" stiffness="0.01" damping="1.0" width="0.002">
                <site site="site_z_front_0"/>
<site site="site_z_front_1"/>
<site site="site_z_front_2"/>
<site site="site_z_front_3"/>
<site site="site_z_front_4"/>
<site site="site_z_front_5"/>
<site site="site_z_front_6"/>
<site site="site_z_front_7"/>
<site site="site_z_front_8"/>
<site site="site_z_front_9"/>
<site site="site_z_front_10"/>
            </spatial>
        </tendon>
    
        <tendon>
            <spatial name="tendon_z_back" stiffness="0.01" damping="1.0" width="0.002">
                <site site="site_z_back_0"/>
<site site="site_z_back_1"/>
<site site="site_z_back_2"/>
<site site="site_z_back_3"/>
<site site="site_z_back_4"/>
<site site="site_z_back_5"/>
<site site="site_z_back_6"/>
<site site="site_z_back_7"/>
<site site="site_z_back_8"/>
<site site="site_z_back_9"/>
<site site="site_z_back_10"/>
            </spatial>
        </tendon>
    

        <actuator>
            <muscle tendon="tendon_y_front"/> <muscle tendon="tendon_y_back"/> <muscle tendon="tendon_z_front"/> <muscle tendon="tendon_z_back"/> 
        </actuator>

    </mujoco>
    